Workbook
Name Slicer_Channel: #N/A
Name Slicer_Country: #N/A
Name Slicer_Month: #N/A
Name Slicer_ProductCategory: #N/A
Name Slicer_Region: #N/A
Name Slicer_Salesperson: #N/A

Sheet Data
A1: OrderID | B1: OrderDate | C1: RequiredDate | D1: Region | E1: Country | F1: City | G1: CustomerSegment | H1: Channel | I1: Salesperson | J1: ProductCategory | K1: SKU | L1: UnitCost | M1: UnitPrice | N1: DiscountPct | O1: Quantity
A2: ORD-2024-275203 | B2: 45362 | C2: 45388 | D2: Africa | E2: Kenya | F2: Kisumu | G2: Corporate | H2: Retail | I2: C. Otieno | J2: Components | K2: CMP-8270 | L2: 279.24 | M2: 608.9 | N2: 0.112 | O2: 9
A3: ORD-2024-358795 | B3: 45588 | C3: 45587 | D3: Africa | E3: Nigeria | F3: Port Harcourt | G3: Education | H3: Online | I3: J. Njeri | J3: Printers | K3: PRN-9322 | L3: 1084.39 | M3: 759.33 | N3: 0.237 | O3: 31
A4: ORD-2023-373538 | B4: 44985 | C4: 45010 | D4: Africa | E4: Kenya | F4: Nairobi | G4: Corporate | H4: Retail | I4: I. Johnson | J4: Networking | K4: NET-9666 | L4: 1460.76 | M4: -30.66 | N4: 0.131 | O4: 12
A5: ORD-2025-168148 | B5: 45745 | C5: 45749 | D5: Africa | E5: Nigeria | F5: Lagos | G5: Non-Profit | H5: Marketplace | I5: G. Dubois | J5: Phones | K5: PHN-4556 | L5: 259.93 | M5: 255.94 | N5: 0.072 | O5: 22
A6: ORD-2023-824839 | B6: 45266 | C6: 45291 | D6: Asia | E6: Japan | F6: Osaka | G6: Consumer | H6: Retail | I6: L. Okafor | J6: Printers | K6: PRN-8041 | L6: 663.03 | M6: 813.51 | N6: 0.102 | O6: 15
A7: ORD-2023-723587 | B7: 44928 | C7: 44931 | D7: Americas | E7: Canada | F7: Toronto | G7: Corporate | H7: Distributor | I7: B. Chen | J7: Laptops | K7: LAP-8555 | L7: 315.87 | M7: 591.68 | N7: 0 | O7: 7
A8: ORD-2024-336584 | B8: 45653 | C8: 45671 | D8: Asia | E8: India | F8: Bengaluru | G8: Small Business | H8: Marketplace | I8: E. Garcia | J8: Monitors | K8: MON-8629 | L8: 586.07 | M8: 845.97 | N8: 0.147 | O8: 4
A9: ORD-2023-112666 | B9: 44941 | C9: 44939 | D9: Africa | E9: Nigeria | F9: Abuja | G9: Education | H9: Online | I9: O. Wang | J9: Printers | K9: PRN-6276 | L9: 28.38 | M9: 47.22 | N9: 0.194 | O9: 18
A10: ORD-2024-589570 | B10: 45416 | C10: 45441 | D10: Africa | E10: Nigeria | F10: Abuja | G10: Non-Profit | H10: Marketplace | I10: O. Wang | J10: Monitors | K10: MON-6892 | L10: 1295.34 | M10: 2530.81 | N10: 0.031 | O10: 6
A11: ORD-2025-997421 | B11: 45798 | C11: 45817 | D11: Americas | E11: Brazil | F11: São Paulo | G11: Non-Profit | H11: Online | I11: A. Patel | J11: Components | K11: CMP-3731 | L11: 1331.38 | M11: 2309.56 | N11: 0.149 | O11: 31
A12: ORD-2024-210687 | B12: 45319 | C12: 45331 | D12: Europe | E12: Germany | F12: Berlin | G12: Corporate | H12: Online | I12: G. Dubois | J12: Accessories | K12: ACC-7938 | L12: 644.17 | M12: 700.12 | N12: 0.006 | O12: 23
A13: ORD-2025-515515 | B13: 45660 | C13: 45680 | D13: Asia | E13: Japan | F13: Osaka | G13: Corporate | H13: Distributor | I13: F. Müller | J13: Phones | K13: PHN-7019 | L13: 908.6 | M13: 691.37 | N13: 0.25 | O13: 20
... A34: ORD-2025-474710 | B34: 45862 | C34: 45875 | D34: Africa | E34: South Africa | F34: Johannesburg | G34: Education | H34: Marketplace | I34: D. Smith | J34: Networking | K34: NET-7966 | L34: 1463.9 | M34: 2633.02 | N34: 0.084 | O34: 4
A35: ORD-2024-629525 | B35: 45400 | C35: 45420 | D35: Europe | E35: United Kingdom | F35: London | G35: Non-Profit | I35: D. Smith | J35: Laptops | K35: LAP-9932 | L35: 645.33 | M35: 1321.85 | N35: 0 | O35: 10
A36: ORD-2024-167215 | B36: 45527 | C36: 45525 | D36: Africa | E36: South Africa | F36: Johannesburg | G36: Education | H36: Retail | I36: E. Garcia | J36: Components | K36: CMP-1559 | L36: 1432.52 | M36: 3036.87 | N36: 0 | O36: 9
A37: ORD-2023-864121 | B37: 45012 | C37: 45038 | D37: Asia | E37: India | F37: Delhi | G37: Non-Profit | H37: Marketplace | I37: J. Njeri | J37: Printers | K37: PRN-4506 | L37: 178.53 | M37: 199.37 | N37: 0.101 | O37: 37
A38: ORD-2024-692673 | B38: 45358 | C38: 45376 | D38: Europe | E38: Germany | F38: Munich | G38: Corporate | H38: Online | I38: B. Chen | J38: Components | K38: CMP-7617 | L38: 712.84 | M38: 927.51 | N38: 0.243 | O38: 27
A39: ORD-2025-718992 | B39: 45832 | C39: 45848 | D39: Asia | E39: China | F39: Shanghai | G39: Enterprise | H39: Direct | I39: N. Brown | J39: Components | K39: CMP-8390 | L39: 757.19 | M39: 1735.41 | N39: 0.136 | O39: 8
A40: ORD-2024-599522 | B40: 45401 | C40: 45418 | D40: Africa | E40: Nigeria | F40: Port Harcourt | G40: Non-Profit | H40: Online | I40: A. Patel | J40: Printers | K40: PRN-7303 | L40: 865.33 | M40: 1395.64 | N40: 0.175 | O40: 13
A41: ORD-2023-651638 | B41: 45094 | C41: 45101 | D41: Americas | E41: USA | F41: San Francisco | G41: Corporate | H41: Retail | I41: I. Johnson | J41: Printers | K41: PRN-6536 | L41: 313.99 | M41: 454.42 | N41: 0.129 | O41: 9
A42: ORD-2024-635626 | B42: 45531 | C42: 45554 | D42: Europe | E42: Germany | F42: Berlin | G42: Small Business | H42: Direct | I42: D. Smith | J42: Monitors | K42: MON-9967 | L42: 1024.01 | M42: 1580.97 | N42: 0.037 | O42: 27
A43: ORD-2024-296582 | B43: 45302 | C43: 45324 | D43: Africa | E43: South Africa | F43: Durban | G43: Consumer | H43: Online | I43: K. Singh | J43: Networking | K43: NET-1412 | L43: 1206.2 | M43: 1759.79 | N43: 0 | O43: 6
A44: ORD-2024-998320 | B44: 45590 | C44: 45610 | D44: Africa | E44: Kenya | F44: Mombasa | G44: Corporate | H44: Direct | I44: H. Kim | J44: Printers | K44: PRN-3143 | L44: 1396.48 | M44: 3204.5 | N44: 0.318 | O44: 14
A45: ORD-2025-820255 | B45: 45806 | C45: 45828 | D45: Europe | E45: Germany | F45: Berlin | G45: Corporate | H45: Direct | I45: A. Patel | J45: Printers | K45: PRN-9787 | L45: 483.47 | M45: 1135.43 | N45: 0.146 | O45: 11
A46: ORD-2024-389336 | B46: 45432 | C46: 45445 | D46: Americas | E46: Canada | F46: Vancouver | G46: Enterprise | H46: Marketplace | I46: K. Singh | J46: Components | K46: CMP-5946 | L46: 675.43 | M46: 996.36 | N46: 0.182 | O46: 22
A47: ORD-2023-308124 | B47: 45035 | C47: 45046 | D47: Asia | E47: India | F47: Delhi | G47: Small Business | H47: Retail | I47: A. Patel | J47: Networking | K47: NET-2062 | L47: 826.55 | M47: 1397.05 | N47: 0.169 | O47: 28
... A77: ORD-2023-722117 | B77: 45187 | C77: 45207 | D77: Asia | E77: India | F77: Delhi | G77: Small Business | H77: Direct | I77: B. Chen | J77: Components | K77: CMP-1009 | L77: 825.64 | M77: 1108.43 | N77: 0.114 | O77: 7
A78: ORD-2024-446699 | B78: 45532 | C78: 45560 | D78: Americas | E78: Brazil | F78: Rio de Janeiro | G78: Non-Profit | H78: Online | J78: Accessories | K78: ACC-4490 | L78: 1394.65 | M78: 3144.1 | N78: 0.134 | O78: 13
A79: ORD-2024-451005 | B79: 45473 | C79: 45471 | D79: Americas | E79: Brazil | F79: Rio de Janeiro | G79: Small Business | H79: Direct | I79: L. Okafor | J79: Accessories | K79: ACC-9162 | L79: 1112.98 | M79: 2095.73 | N79: 0.072 | O79: 17
A80: ORD-2023-290279 | B80: 45091 | C80: 45093 | D80: Europe | E80: United Kingdom | F80: Manchester | G80: Non-Profit | H80: Direct | I80: K. Singh | J80: Components | K80: CMP-5820 | L80: 357.36 | M80: 703.62 | N80: 0.257 | O80: 20
A81: ORD-2024-192263 | B81: 45617 | C81: 45647 | D81: Europe | E81: France | F81: Marseille | G81: Small Business | H81: Direct | I81: I. Johnson | J81: Monitors | K81: MON-7943 | L81: 1122.68 | M81: 1997.19 | N81: 0.186 | O81: 3
A82: ORD-2023-159379 | B82: 44965 | C82: 44968 | D82: Africa | E82: South Africa | F82: Cape Town | G82: Corporate | H82: Direct | I82: M. Rossi | J82: Networking | K82: NET-5018 | L82: 1410.05 | M82: 2763.95 | N82: 0.161 | O82: 26
A83: ORD-2023-343322 | B83: 45157 | C83: 45181 | D83: Americas | E83: Canada | F83: Vancouver | G83: Enterprise | H83: Retail | I83: I. Johnson | J83: Printers | K83: PRN-9669 | L83: 1183.95 | M83: 1503.53 | N83: 0.241 | O83: 16
A84: ORD-2025-114382 | B84: 45791 | C84: 45801 | D84: Europe | E84: France | F84: Paris | G84: Small Business | H84: Marketplace | I84: K. Singh | J84: Components | K84: CMP-2865 | L84: 170.39 | M84: 388.04 | N84: 0.084 | O84: 15
A85: ORD-2025-488349 | B85: 45770 | C85: 45769 | D85: Americas | E85: USA | F85: San Francisco | G85: Non-Profit | H85: Distributor | I85: D. Smith | J85: Monitors | K85: MON-3371 | L85: 23.24 | M85: 44.57 | N85: 0.215 | O85: 15
A86: ORD-2025-330203 | B86: 45741 | C86: 45764 | D86: Europe | E86: United Kingdom | F86: London | G86: Consumer | H86: Retail | I86: H. Kim | J86: Networking | K86: NET-7166 | L86: 1421.19 | M86: 1808.26 | N86: 0.104 | O86: 13
A87: ORD-2023-841426 | B87: 45282 | C87: 45283 | D87: Africa | E87: South Africa | F87: Cape Town | G87: Non-Profit | H87: Marketplace | I87: D. Smith | J87: Components | K87: CMP-4531 | L87: 1186.18 | M87: 1285.09 | N87: 0.07 | O87: 11
A88: ORD-2024-594592 | B88: 45388 | C88: 45407 | D88: Asia | E88: China | F88: Shanghai | G88: Corporate | H88: Retail | I88: K. Singh | J88: Components | K88: CMP-8196 | L88: 1366.48 | M88: 1678.14 | N88: 0.154 | O88: 10
A89: ORD-2025-863978 | B89: 45876 | C89: 45888 | D89: Africa | E89: Kenya | F89: Nakuru | G89: Corporate | I89: M. Rossi | J89: Components | K89: CMP-2854 | L89: 601.51 | M89: 679.35 | N89: 0.188 | O89: 3
...

Sheet Cohort Analysis
A3: Sum of GrossRevenue | B3: Column Labels
A4: Row Labels | B4: 0 | C4: 1 | D4: 2 | E4: 3 | F4: 4 | G4: 5 | H4: 6 | I4: 7 | J4: 8 | K4: 9 | L4: 10 | M4: 11 | N4: 12 | O4: 13 | P4: 14 | Q4: 15 | R4: 16 | S4: 17 | T4: 18 | U4: 19 | V4: 21 | W4: 22 | X4: 23 | Y4: 24 | Z4: 25 | AA4: 26 | AB4: 28 | AC4: 29 | AD4: 30 | AE4: 31 | AF4: 32 | AG4: Grand Total
A5: Brazil | I5: 7235.2135 | K5: 16213.633 | L5: 7854.6694 | S5: 41658.527 | U5: 35396.278 | AD5: 38096.184 | AF5: 7597.4998 | AG5: 154052
A6: Canada | G6: 11283.401 | J6: 15530.93 | T6: 79082.507 | W6: 14894.904 | X6: 20713.04 | AG6: 141504.78
A7: China | M7: 23668.56 | O7: 1446.9507 | T7: 22526.66 | W7: 4071.8 | AG7: 51713.971
A8: France | E8: 9022.35 | G8: 10388.43 | M8: 24278.849 | Y8: 12699.28 | Z8: 12040.644 | AC8: 8366.02 | AG8: 76795.573
A9: Germany | E9: 22620.86 | F9: 17964.404 | N9: 16006.143 | P9: 10647.727 | Q9: 13321.14 | X9: 4790.1068 | Z9: 30546.068 | AC9: 6066.5465 | AG9: 121963
A10: India | B10: 26759.288 | F10: 46450.26 | G10: 4577.148 | I10: 7105.3528 | J10: 31513.085 | R10: 11859.695 | W10: 10893.623 | AC10: 7969.4615 | AG10: 147127.91
A11: Japan | C11: 13856.524 | R11: 14549.029 | X11: 7689.456 | AA11: 14431.738 | AB11: 7507.4515 | AG11: 58034.199
A12: Kenya | D12: 53034.364 | H12: 27465.648 | J12: 1030.7574 | K12: 11015.51 | R12: 13108.786 | S12: 549.8001 | Y12: 28386.016 | Z12: 15860.782 | AB12: 4569.8508 | AD12: 10693.885 | AG12: 165715.4
A13: Nigeria | C13: 4737.2198 | H13: 29574.105 | Q13: 1547.35 | R13: 34139.16 | S13: 2719.8567 | V13: 20079.344 | AA13: 47502.705 | AB13: 1010.3759 | AC13: 10936.992 | AD13: 17847.907 | AE13: 19066.045 | AG13: 189161.06
A14: South Africa | F14: 10759.224 | H14: 20430.772 | N14: 26765.04 | AG14: 57955.036
A15: United Kingdom | B15: 19628.477 | D15: 16013.682 | G15: 6732.4334 | I15: 7382.145 | K15: 23375.594 | L15: 5610.0924 | N15: 23195.018 | S15: 35167.745 | AG15: 137105.19
A16: USA | H16: 32086.376 | J16: 908.037 | K16: 5533.623 | Y16: 2117.4835 | AG16: 40645.519
A17: Grand Total | B17: 46387.765 | C17: 18593.744 | D17: 69048.046 | E17: 31643.21 | F17: 75173.888 | G17: 32981.412 | H17: 109556.9 | I17: 21722.711 | J17: 48982.809 | K17: 56138.36 | L17: 13464.762 | M17: 47947.409 | N17: 65966.202 | O17: 1446.9507 | P17: 10647.727 | Q17: 14868.49 | R17: 73656.67 | S17: 80095.929 | T17: 101609.17 | U17: 35396.278 | V17: 20079.344 | W17: 29860.327 | X17: 33192.603 | Y17: 43202.779 | Z17: 58447.494 | AA17: 61934.444 | AB17: 13087.678 | AC17: 33339.02 | AD17: 66637.976 | AE17: 19066.045 | AF17: 7597.4998 | AG17: 1341773.6

Sheet SKU
A3: Row Labels | B3: Sum of GrossRevenue | C3: Sum of GrossRevenue2
A4: Accessories | B4: 1341773.6
A5: ACC-6626 | B5: 79082.507 | C5: 0.058938784
A6: ACC-2988 | B6: 53034.364 | C6: 0.098464351
A7: ACC-9283 | B7: 46450.26 | C7: 0.1330829
A8: ACC-9533 | B8: 43084.872 | C8: 0.16519329
A9: ACC-8098 | B9: 38096.184 | C9: 0.1935857
A10: ACC-4490 | B10: 35396.278 | C10: 0.21996591
A11: ACC-7838 | B11: 35167.745 | C11: 0.24617581
A12: ACC-5177 | B12: 34139.16 | C12: 0.27161912
A13: ACC-9162 | B13: 33062.236 | C13: 0.29625981
A14: ACC-7078 | B14: 32086.376 | C14: 0.32017322
A15: ACC-1375 | B15: 31513.085 | C15: 0.34365936
A16: ACC-1659 | B16: 28386.016 | C16: 0.36481495
... A92: ACC-1770 | B92: 0 | C92: 1
A93: Grand Total | B93: 1341773.6

Sheet ABC
A1: Row Labels | B1: Sum of GrossRevenue | C1: Sum of GrossRevenue2 | D1: ABC_Class
A2: Accessories | B2: 1341773.6 | D2: =IF(C3<=0.8,"A",IF(C3<=0.95,"B","C")) -> A
A3: ACC-6626 | B3: 79082.507 | C3: 0.058938784 | D3: =IF(C4<=0.8,"A",IF(C4<=0.95,"B","C")) -> A
A4: ACC-2988 | B4: 53034.364 | C4: 0.098464351 | D4: =IF(C5<=0.8,"A",IF(C5<=0.95,"B","C")) -> A
A5: ACC-9283 | B5: 46450.26 | C5: 0.1330829 | D5: =IF(C6<=0.8,"A",IF(C6<=0.95,"B","C")) -> A
A6: ACC-9533 | B6: 43084.872 | C6: 0.16519329 | D6: =IF(C7<=0.8,"A",IF(C7<=0.95,"B","C")) -> A
A7: ACC-8098 | B7: 38096.184 | C7: 0.1935857 | D7: =IF(C8<=0.8,"A",IF(C8<=0.95,"B","C")) -> A
A8: ACC-4490 | B8: 35396.278 | C8: 0.21996591 | D8: =IF(C9<=0.8,"A",IF(C9<=0.95,"B","C")) -> A
A9: ACC-7838 | B9: 35167.745 | C9: 0.24617581 | D9: =IF(C10<=0.8,"A",IF(C10<=0.95,"B","C")) -> A
A10: ACC-5177 | B10: 34139.16 | C10: 0.27161912 | D10: =IF(C11<=0.8,"A",IF(C11<=0.95,"B","C")) -> A
A11: ACC-9162 | B11: 33062.236 | C11: 0.29625981 | D11: =IF(C12<=0.8,"A",IF(C12<=0.95,"B","C")) -> A
A12: ACC-7078 | B12: 32086.376 | C12: 0.32017322 | D12: =IF(C13<=0.8,"A",IF(C13<=0.95,"B","C")) -> A
A13: ACC-1375 | B13: 31513.085 | C13: 0.34365936 | D13: =IF(C14<=0.8,"A",IF(C14<=0.95,"B","C")) -> A
A14: ACC-1659 | B14: 28386.016 | C14: 0.36481495 | D14: =IF(C15<=0.8,"A",IF(C15<=0.95,"B","C")) -> A
... A90: ACC-1770 | B90: 0 | C90: 1 | D90: =IF(C91<=0.8,"A",IF(C91<=0.95,"B","C")) -> A
A91: Components | B91: 1550200.5 | D91: =IF(C92<=0.8,"A",IF(C92<=0.95,"B","C")) -> A
A92: CMP-8851 | B92: 139277.83 | C92: 0.089845041 | D92: =IF(C93<=0.8,"A",IF(C93<=0.95,"B","C")) -> A
A93: CMP-3938 | B93: 84136.12 | C93: 0.14411939 | D93: =IF(C94<=0.8,"A",IF(C94<=0.95,"B","C")) -> A
A94: CMP-2040 | B94: 65111.386 | C94: 0.1861213 | D94: =IF(C95<=0.8,"A",IF(C95<=0.95,"B","C")) -> A
A95: CMP-3731 | B95: 60928.502 | C95: 0.22542492 | D95: =IF(C96<=0.8,"A",IF(C96<=0.95,"B","C")) -> A
A96: CMP-2096 | B96: 52361.645 | C96: 0.25920226 | D96: =IF(C97<=0.8,"A",IF(C97<=0.95,"B","C")) -> A
A97: CMP-8127 | B97: 50296.415 | C97: 0.29164736 | D97: =IF(C98<=0.8,"A",IF(C98<=0.95,"B","C")) -> A
A98: CMP-5006 | B98: 41419.524 | C98: 0.31836618 | D98: =IF(C99<=0.8,"A",IF(C99<=0.95,"B","C")) -> A
A99: CMP-1940 | B99: 40476.013 | C99: 0.34447636 | D99: =IF(C100<=0.8,"A",IF(C100<=0.95,"B","C")) -> A
A100: CMP-8002 | B100: 33687.502 | C100: 0.36620742 | D100: =IF(C101<=0.8,"A",IF(C101<=0.95,"B","C")) -> A
A101: CMP-1156 | B101: 33308.55 | C101: 0.38769403 | D101: =IF(C102<=0.8,"A",IF(C102<=0.95,"B","C")) -> A
A102: CMP-6529 | B102: 32335.218 | C102: 0.40855276 | D102: =IF(C103<=0.8,"A",IF(C103<=0.95,"B","C")) -> A
A103: CMP-6971 | B103: 27701.57 | C103: 0.42642243 | D103: =IF(C104<=0.8,"A",IF(C104<=0.95,"B","C")) -> A
... A181: CMP-1632 | B181: 97.0154 | C181: 1 | D181: =IF(C182<=0.8,"A",IF(C182<=0.95,"B","C")) -> A
A182: Laptops | B182: 1711094.4 | D182: =IF(C183<=0.8,"A",IF(C183<=0.95,"B","C")) -> A
A183: LAP-8910 | B183: 102122.94 | C183: 0.059682823 | D183: =IF(C184<=0.8,"A",IF(C184<=0.95,"B","C")) -> A
A184: LAP-3904 | B184: 82514.712 | C184: 0.10790618 | D184: =IF(C185<=0.8,"A",IF(C185<=0.95,"B","C")) -> A
A185: LAP-8214 | B185: 65119.33 | C185: 0.1459633 | D185: =IF(C186<=0.8,"A",IF(C186<=0.95,"B","C")) -> A
A186: LAP-5763 | B186: 65066.934 | C186: 0.1839898 | D186: =IF(C187<=0.8,"A",IF(C187<=0.95,"B","C")) -> A
A187: LAP-6499 | B187: 64192.977 | C187: 0.22150555 | D187: =IF(C188<=0.8,"A",IF(C188<=0.95,"B","C")) -> A
A188: LAP-1739 | B188: 58526.831 | C188: 0.25570987 | D188: =IF(C189<=0.8,"A",IF(C189<=0.95,"B","C")) -> A
A189: LAP-8825 | B189: 58057.65 | C189: 0.28964 | D189: =IF(C190<=0.8,"A",IF(C190<=0.95,"B","C")) -> A
A190: LAP-7523 | B190: 44173.628 | C190: 0.31545601 | D190: =IF(C191<=0.8,"A",IF(C191<=0.95,"B","C")) -> A
A191: LAP-1308 | B191: 42433.254 | C191: 0.34025491 | D191: =IF(C192<=0.8,"A",IF(C192<=0.95,"B","C")) -> A
A192: LAP-1178 | B192: 41914.216 | C192: 0.36475047 | D192: =IF(C193<=0.8,"A",IF(C193<=0.95,"B","C")) -> A
...

Sheet salespersons
A3: Row Labels | B3: Count of OrderID | C3: Sum of GrossRevenue | D3: Sum of GrossProfit | E3: Revenue per Order | F3: Gross Profit Per Order
A4: A. Patel | B4: 10 | C4: 114205.92 | D4: 31750.386 | E4: =C4/B4 -> 11420.592 | F4: =D4/B4 -> 3175.0386
A5: B. Chen | B5: 6 | C5: 121530.74 | D5: 24662.766 | E5: =C5/B5 -> 20255.123 | F5: =D5/B5 -> 4110.4609
A6: C. Otieno | B6: 4 | C6: 84749.381 | D6: 19069.351 | E6: =C6/B6 -> 21187.345 | F6: =D6/B6 -> 4767.3377
A7: D. Smith | B7: 5 | C7: 111804.06 | D7: 37505.062 | E7: =C7/B7 -> 22360.812 | F7: =D7/B7 -> 7501.0124
A8: E. Garcia | B8: 1 | C8: 4577.148 | D8: 1230.298 | E8: =C8/B8 -> 4577.148 | F8: =D8/B8 -> 1230.298 | J8: average order value
A9: F. Müller | B9: 6 | C9: 98847.877 | D9: 35544.327 | E9: =C9/B9 -> 16474.646 | F9: =D9/B9 -> 5924.0545 | J9: =10944328.86/632 -> 17316.976
A10: G. Dubois | B10: 6 | C10: 133482.19 | D10: 41506.989 | E10: =C10/B10 -> 22247.032 | F10: =D10/B10 -> 6917.8315
A11: H. Kim | B11: 6 | C11: 49428.145 | D11: -60210.815 | E11: =C11/B11 -> 8238.0242 | F11: =D11/B11 -> -10035.136
A12: I. Johnson | B12: 5 | C12: 38245.332 | D12: 8772.6924 | E12: =C12/B12 -> 7649.0665 | F12: =D12/B12 -> 1754.5385
A13: J. Njeri | B13: 4 | C13: 125092.17 | D13: 54633.286 | E13: =C13/B13 -> 31273.042 | F13: =D13/B13 -> 13658.322
A14: K. Singh | B14: 4 | C14: 30378.708 | D14: 6306.6176 | E14: =C14/B14 -> 7594.6769 | F14: =D14/B14 -> 1576.6544
A15: L. Okafor | B15: 14 | C15: 192479.23 | D15: 56612.847 | E15: =C15/B15 -> 13748.516 | F15: =D15/B15 -> 4043.7748
A16: M. Rossi | B16: 8 | C16: 122010.26 | D16: 29183.088 | E16: =C16/B16 -> 15251.282 | F16: =D16/B16 -> 3647.886
A17: O. Wang | B17: 7 | C17: 71977.254 | D17: 23567.304 | E17: =C17/B17 -> 10282.465 | F17: =D17/B17 -> 3366.7577
A18: Unassigned | B18: 2 | C18: 42965.241 | D18: 13379.751 | E18: =C18/B18 -> 21482.62 | F18: =D18/B18 -> 6689.8755
A19: Grand Total | B19: 88 | C19: 1341773.6 | D19: 323513.95 | E19: =C19/B19 -> 15247.428 | F19: =D19/B19 -> 3676.2949

Sheet per month
A3: Count of OrderID | B3: Column Labels | AJ3: Average Orders per Active Month
A4: Row Labels | B4: Apr-2023 | C4: Apr-2024 | D4: Aug-2023 | E4: Aug-2024 | F4: Aug-2025 | G4: Dec-2023 | H4: Dec-2024 | I4: Feb-2023 | J4: Feb-2024 | K4: Feb-2025 | L4: Jan-2023 | M4: Jan-2024 | N4: Jan-2025 | O4: Jul-2023 | P4: Jul-2024 | Q4: Jul-2025 | R4: Jun-2023 | S4: Jun-2024 | T4: Jun-2025 | U4: Mar-2023 | V4: Mar-2024 | W4: Mar-2025 | X4: May-2023 | Y4: May-2024 | Z4: May-2025 | AA4: Nov-2023 | AB4: Nov-2024 | AC4: Oct-2023 | AD4: Oct-2024 | AE4: Sept-2023 | AF4: Sept-2025 | AG4: Grand Total | AJ4: =AVERAGEIF(B5:AI5,">0") -> 1.8181818
A5: A. Patel | B5: 1 | C5: 1 | F5: 1 | G5: 1 | S5: 1 | T5: 1 | Z5: 1 | AB5: 1 | AC5: 1 | AE5: 1 | AG5: 10 | AJ5: =AVERAGEIF(B6:AI6,">0") -> 1.7142857
A6: B. Chen | B6: 1 | L6: 1 | N6: 1 | O6: 1 | Q6: 1 | AE6: 1 | AG6: 6 | AJ6: =AVERAGEIF(B7:AI7,">0") -> 1.6
A7: C. Otieno | H7: 1 | S7: 1 | T7: 1 | U7: 1 | AG7: 4 | AJ7: =AVERAGEIF(B8:AI8,">0") -> 1.6666667
A8: D. Smith | I8: 1 | M8: 1 | P8: 1 | X8: 1 | AB8: 1 | AG8: 5 | AJ8: =AVERAGEIF(B9:AI9,">0") -> 1
A9: E. Garcia | R9: 1 | AG9: 1 | AJ9: =AVERAGEIF(B10:AI10,">0") -> 1.7142857
A10: F. Müller | H10: 1 | M10: 1 | Y10: 1 | Z10: 1 | AB10: 1 | AD10: 1 | AG10: 6 | AJ10: =AVERAGEIF(B11:AI11,">0") -> 1.7142857
A11: G. Dubois | L11: 1 | M11: 1 | N11: 1 | P11: 1 | Q11: 1 | W11: 1 | AG11: 6 | AJ11: =AVERAGEIF(B12:AI12,">0") -> 2
A12: H. Kim | T12: 1 | W12: 1 | Y12: 2 | Z12: 1 | AA12: 1 | AG12: 6 | AJ12: =AVERAGEIF(B13:AI13,">0") -> 2.5
A13: I. Johnson | O13: 2 | R13: 1 | AE13: 2 | AG13: 5 | AJ13: =AVERAGEIF(B14:AI14,">0") -> 1.6
A14: J. Njeri | D14: 1 | N14: 1 | P14: 1 | R14: 1 | AG14: 4 | AJ14: =AVERAGEIF(B15:AI15,">0") -> 2
A15: K. Singh | K15: 1 | X15: 2 | AF15: 1 | AG15: 4 | AJ15: =AVERAGEIF(B16:AI16,">0") -> 2.5454545
A16: L. Okafor | D16: 1 | G16: 1 | H16: 1 | J16: 1 | K16: 4 | S16: 2 | U16: 1 | AA16: 1 | AC16: 1 | AF16: 1 | AG16: 14 | AJ16: =AVERAGEIF(B17:AI17,">0") -> 2
A17: M. Rossi | B17: 1 | O17: 2 | Q17: 1 | R17: 1 | S17: 1 | T17: 1 | V17: 1 | AG17: 8 | AJ17: =AVERAGEIF(B18:AI18,">0") -> 2
A18: O. Wang | C18: 1 | D18: 1 | Q18: 1 | T18: 1 | X18: 1 | AC18: 2 | AG18: 7 | AJ18: =AVERAGEIF(B19:AI19,">0") -> 1.3333333
A19: Unassigned | E19: 1 | AC19: 1 | AG19: 2 | AJ19: =AVERAGEIF(B20:AI20,">0") -> 5.5
A20: Grand Total | B20: 3 | C20: 2 | D20: 3 | E20: 1 | F20: 1 | G20: 2 | H20: 3 | I20: 1 | J20: 1 | K20: 5 | L20: 2 | M20: 3 | N20: 3 | O20: 5 | P20: 3 | Q20: 4 | R20: 4 | S20: 5 | T20: 5 | U20: 2 | V20: 1 | W20: 2 | X20: 4 | Y20: 3 | Z20: 3 | AA20: 2 | AB20: 3 | AC20: 5 | AD20: 1 | AE20: 4 | AF20: 2 | AG20: 88 | AJ20: =AVERAGEIF(B21:AI21,">0") -> #DIV/0!

Sheet Channel Mix
B3: Column Labels | P3: Cannibalization
B4: Direct | D4: Distributor | F4: Marketplace | H4: Online | J4: Retail | L4: Uknown | N4: Total Sum of GrossRevenue | O4: Total Revenue Share %
A5: Row Labels | B5: Sum of GrossRevenue | C5: Revenue Share % | D5: Sum of GrossRevenue | E5: Revenue Share % | F5: Sum of GrossRevenue | G5: Revenue Share % | H5: Sum of GrossRevenue | I5: Revenue Share % | J5: Sum of GrossRevenue | K5: Revenue Share % | L5: Sum of GrossRevenue | M5: Revenue Share %
A6: Africa | B6: 86488.183 | C6: 0.20949996 | D6: 106038.14 | E6: 0.25685574 | F6: 42611.449 | G6: 0.10321753 | H6: 38709.011 | I6: 0.093764674 | J6: 138984.71 | K6: 0.33666209 | M6: 0 | N6: 412831.5 | O6: 1 | P6: =IF(I6>K6, "Possible Cannibalization","Balanced Mix") -> Balanced Mix
A7: Americas | B7: 140889.88 | C7: 0.4190628 | D7: 36642.16 | E7: 0.10898843 | F7: 61611.596 | G7: 0.18325751 | H7: 37513.761 | I7: 0.11158092 | J7: 59544.907 | K7: 0.17711035 | M7: 0 | N7: 336202.31 | O7: 1 | P7: =IF(I7>K7, "Possible Cannibalization","Balanced Mix") -> Balanced Mix
A8: Asia | C8: 0 | D8: 13208.207 | E8: 0.051418593 | F8: 29161.833 | G8: 0.11352491 | H8: 11859.695 | I8: 0.046168935 | J8: 171133.26 | K8: 0.66620941 | L8: 31513.085 | M8: 0.12267816 | N8: 256876.08 | O8: 1 | P8: =IF(I8>K8, "Possible Cannibalization","Balanced Mix") -> Balanced Mix
A9: Europe | B9: 98133.33 | C9: 0.29218196 | D9: 50205.64 | E9: 0.14948216 | F9: 78851.603 | G9: 0.23477259 | H9: 39353.151 | I9: 0.11716998 | J9: 69320.031 | K9: 0.20639331 | M9: 0 | N9: 335863.75 | O9: 1 | P9: =IF(I9>K9, "Possible Cannibalization","Balanced Mix") -> Balanced Mix
A10: Grand Total | B10: 325511.39 | C10: 0.24259784 | D10: 206094.15 | E10: 0.1535983 | F10: 212236.48 | G10: 0.15817607 | H10: 127435.62 | I10: 0.094975497 | J10: 438982.92 | K10: 0.32716615 | L10: 31513.085 | M10: 0.023486141 | N10: 1341773.6 | O10: 1

Sheet Service Level 
A3: Row Labels | B3: Count of OrderID | C3: Sum of OnTimeFlag | E3: OnTime %
A4: Brazil | B4: 10 | C4: 4 | E4: =IF(B4=0,"",C4/B4) -> 0.4
A5: Accessories | B5: 10 | C5: 4 | E5: =IF(B5=0,"",C5/B5) -> 0.4
A6: Canada | B6: 6 | C6: 2 | E6: =IF(B6=0,"",C6/B6) -> 0.33333333
A7: Accessories | B7: 6 | C7: 2 | E7: =IF(B7=0,"",C7/B7) -> 0.33333333
A8: China | B8: 4 | C8: 3 | E8: =IF(B8=0,"",C8/B8) -> 0.75
A9: Accessories | B9: 4 | C9: 3 | E9: =IF(B9=0,"",C9/B9) -> 0.75
A10: France | B10: 7 | C10: 1 | E10: =IF(B10=0,"",C10/B10) -> 0.14285714
A11: Accessories | B11: 7 | C11: 1 | E11: =IF(B11=0,"",C11/B11) -> 0.14285714
A12: Germany | B12: 9 | C12: 4 | E12: =IF(B12=0,"",C12/B12) -> 0.44444444
A13: Accessories | B13: 9 | C13: 4 | E13: =IF(B13=0,"",C13/B13) -> 0.44444444
A14: India | B14: 8 | C14: 2 | E14: =IF(B14=0,"",C14/B14) -> 0.25
A15: Accessories | B15: 8 | C15: 2 | E15: =IF(B15=0,"",C15/B15) -> 0.25
... A28: Grand Total | B28: 88 | C28: 32 | E28: =IF(B28=0,"",C28/B28) -> 0.36363636
E29: =IF(B29=0,"",C29/B29)
E30: =IF(B30=0,"",C30/B30)
E31: =IF(B31=0,"",C31/B31)
E32: =IF(B32=0,"",C32/B32)
E33: =IF(B33=0,"",C33/B33)
E34: =IF(B34=0,"",C34/B34)
E35: =IF(B35=0,"",C35/B35)
E36: =IF(B36=0,"",C36/B36)
E37: =IF(B37=0,"",C37/B37)
E38: =IF(B38=0,"",C38/B38)
E39: =IF(B39=0,"",C39/B39)
E40: =IF(B40=0,"",C40/B40)
... E100: =IF(B100=0,"",C100/B100)

Sheet Price Compliance
A3: Row Labels | B3: Count of OrderID | C3: Discounted Orders | D3: % of Orders
A4: Africa | B4: 27 | C4: 5 | D4: =IF(B4=0,"",C4/B4) -> 0.18518519
A5: A. Patel | B5: 4 | C5: 2 | D5: =IF(B5=0,"",C5/B5) -> 0.5
A6: B. Chen | B6: 1 | C6: 0 | D6: =IF(B6=0,"",C6/B6) -> 0
A7: C. Otieno | B7: 1 | C7: 0 | D7: =IF(B7=0,"",C7/B7) -> 0
A8: D. Smith | B8: 1 | C8: 0 | D8: =IF(B8=0,"",C8/B8) -> 0
A9: F. Müller | B9: 4 | C9: 0 | D9: =IF(B9=0,"",C9/B9) -> 0
A10: G. Dubois | B10: 1 | C10: 0 | D10: =IF(B10=0,"",C10/B10) -> 0
A11: H. Kim | B11: 2 | C11: 0 | D11: =IF(B11=0,"",C11/B11) -> 0
A12: I. Johnson | B12: 3 | C12: 1 | D12: =IF(B12=0,"",C12/B12) -> 0.33333333
A13: J. Njeri | B13: 1 | C13: 0 | D13: =IF(B13=0,"",C13/B13) -> 0
A14: K. Singh | B14: 2 | C14: 0 | D14: =IF(B14=0,"",C14/B14) -> 0
A15: L. Okafor | B15: 1 | C15: 0 | D15: =IF(B15=0,"",C15/B15) -> 0
... A53: Grand Total | B53: 88 | C53: 15 | D53: =IF(B53=0,"",C53/B53) -> 0.17045455
D54: =IF(B54=0,"",C54/B54)
D55: =IF(B55=0,"",C55/B55)
D56: =IF(B56=0,"",C56/B56)
D57: =IF(B57=0,"",C57/B57)
D58: =IF(B58=0,"",C58/B58)
D59: =IF(B59=0,"",C59/B59)
D60: =IF(B60=0,"",C60/B60)
D61: =IF(B61=0,"",C61/B61)
D62: =IF(B62=0,"",C62/B62)
D63: =IF(B63=0,"",C63/B63)
D64: =IF(B64=0,"",C64/B64)
D65: =IF(B65=0,"",C65/B65)
... D71: =IF(B71=0,"",C71/B71)

Sheet Revenue per month
A3: Row Labels | B3: Sum of GrossRevenue
A4: Apr-2023 | B4: 45499.734
A5: Apr-2024 | B5: 14868.49
A6: Aug-2023 | B6: 21722.711
A7: Aug-2024 | B7: 35396.278
A8: Aug-2025 | B8: 19066.045
A9: Dec-2023 | B9: 47947.409
A10: Dec-2024 | B10: 25503.147
A11: Feb-2023 | B11: 4737.2198
A12: Feb-2024 | B12: 1446.9507
A13: Feb-2025 | B13: 66136.95
A14: Jan-2023 | B14: 46387.765
A15: Jan-2024 | B15: 65966.202
... A35: Grand Total | B35: 1341773.6

Sheet Profit by R n C
A3: Sum of GrossProfit | B3: Column Labels
A4: Row Labels | B4: Direct | C4: Distributor | D4: Marketplace | E4: Online | F4: Retail | G4: Uknown | H4: Grand Total
A5: Africa | B5: 24405.423 | C5: 31999.859 | D5: 16851.859 | E5: 12391.171 | F5: 42270.584 | H5: 127918.9
A6: Americas | B6: 60093.001 | C6: 4520.3998 | D6: 27820.756 | E6: 17820.321 | F6: 8125.0872 | H6: 118379.57
A7: Asia | C7: 4009.3667 | D7: 2147.5234 | E7: 3024.3151 | F7: 29912.053 | G7: 16530.425 | H7: 55623.683
A8: Europe | B8: 29728.7 | C8: 24521.44 | D8: -50030.437 | E8: 3323.7306 | F8: 14048.371 | H8: 21591.805
A9: Grand Total | B9: 114227.12 | C9: 65051.066 | D9: -3210.2986 | E9: 36559.538 | F9: 94356.096 | G9: 16530.425 | H9: 323513.95

Sheet 10 SKU
A3: Row Labels | B3: Sum of GrossRevenue
A4: ACC-6626 | B4: 79082.507
A5: ACC-2988 | B5: 53034.364
A6: ACC-9283 | B6: 46450.26
A7: ACC-9533 | B7: 43084.872
A8: ACC-8098 | B8: 38096.184
A9: ACC-4490 | B9: 35396.278
A10: ACC-7838 | B10: 35167.745
A11: ACC-5177 | B11: 34139.16
A12: ACC-9162 | B12: 33062.236
A13: ACC-7078 | B13: 32086.376
A14: Grand Total | B14: 429599.98

Sheet slicer

Sheet Sheet17
A3: Row Labels | B3: Average of DiscountPct
A4: ACC-1021 | B4: 0.259
A5: ACC-1028 | B5: 0.113
A6: ACC-1060 | B6: 0.028
A7: ACC-1075 | B7: 0.245
A8: ACC-1238 | B8: 0.565
A9: ACC-1249 | B9: 0.098
A10: ACC-1375 | B10: 0.157
A11: ACC-1492 | B11: 0.059
A12: ACC-1596 | B12: 0.083
A13: ACC-1604 | B13: 0.088
A14: ACC-1659 | B14: 0.148
A15: ACC-1663 | B15: 0
... A92: Grand Total | B92: 0.11968182
G602: Row Labels | H602: Average of DiscountPct
G603: ACC-1021 | H603: 0.259
G604: ACC-1028 | H604: 0.113
G605: ACC-1060 | H605: 0.028
G606: ACC-1075 | H606: 0.245
G607: ACC-1238 | H607: 0.565
G608: ACC-1249 | H608: 0.098
G609: ACC-1375 | H609: 0.157
G610: ACC-1492 | H610: 0.059
G611: ACC-1596 | H611: 0.083
G612: ACC-1604 | H612: 0.088
G613: ACC-1659 | H613: 0.148
G614: ACC-1663 | H614: 0
... G1232: PRN-9975 | H1232: 0.032

Sheet Sheet18
A3: Row Labels | B3: Count of OrderID
A4: Africa | B4: 145
A5: Americas | B5: 157
A6: Asia | B6: 171
A7: Europe | B7: 159
A8: Grand Total | B8: 632

Sheet Data_staging
A1: OrderID | B1: OrderDate | C1: RequiredDate_Clean | D1: RequiredDate_Flag | E1: RequiredDate | F1: LeadTimeDays | G1: Region | H1: Country | I1: City | J1: CustomerSegment | K1: Channel | L1: Salesperson | M1: ProductCategory | N1: SKU | O1: UnitCost | P1: UnitPrice_Flag | Q1: UnitPrice_Clean | R1: UnitPrice | S1: Discount_Clean | T1: Discount_Flag | U1: DiscountPct | V1: DiscountFlag | W1: MarginPct | X1: CostOfGoods | Y1: GrossProfit | Z1: GrossRevenue | AA1: Quarter | AB1: Month | AC1: PriceBand | AD1: Quantity | AE1: Country_FirstMonth | AF1: MonthDate | AG1: Quantity_Scenario | AH1: UnitCost_Scenario | AI1: GrossRevenue_Scenario | AJ1: Gross_ProfitScenario | AK1: UnitPrice_Scenario | AL1: OnTimeFlag | AM1: CohortMonth
A2: ORD-2024-275203 | B2: 45362 | C2: =IF(D2="Check",B2+7,E2) -> 45388 | D2: =IF(Table1[[#This Row],[RequiredDate]]<Table1[[#This Row],[OrderDate]],"Check","OK") -> OK | E2: 45388 | F2: =C2-B2 -> 26 | G2: Africa | H2: Kenya | I2: Kisumu | J2: Corporate | K2: Retail | L2: C. Otieno | M2: Components | N2: CMP-8270 | O2: 279.24 | P2: =IF(Table1[[#This Row],[UnitPrice]]<=0,"Check","OK") -> OK | Q2: =IF(R2<0,0,R2) -> 608.9 | R2: 608.9 | S2: =IF(Table1[[#This Row],[Discount_Flag]]="Check", MIN(MAX(Table1[[#This Row],[DiscountPct]],0),0.3), Table1[[#This Row],[DiscountPct]]) -> 0.112 | T2: =IF(OR(Table1[[#This Row],[DiscountPct]]<0,Table1[[#This Row],[DiscountPct]]>0.3),"Check","OK") -> OK | U2: 0.112 | V2: =IF(U2>0.2,1,0) -> 0 | W2: =IF(Z2=0, 0, Y2/Z2) -> 0.48356141 | X2: =O2*AD2 -> 2513.16 | Y2: =Z2-X2 -> 2353.1688 | Z2: =Q2*AD2*(1-S2) -> 4866.3288 | AA2: ="Q"&ROUNDUP(MONTH(B2)/3,0)&"-"&YEAR(B2) -> Q1-2024 | AB2: =TEXT(B2,"MMM-YYYY") -> Mar-2024 | AC2: =IF(Q2<=$AE$639,"Low",IF(Q2<=$AE$641,"Medium","High")) -> Medium | AD2: 9 | AE2: =_xlfn.MINIFS(Table1[MonthDate], Table1[Country], Table1[[#This Row],[Country]]) -> 44927 | AF2: =DATE(YEAR(B2), MONTH(B2), 1) -> 45352 | AG2: =AD2*(1 + Scenario_Control!$B$4) -> 9.9 | AH2: =O2*(1 + Scenario_Control!$B$3) -> 293.202 | AI2: =AK2 * AG2 * (1 - U2) -> 1070.5923 | AJ2: =AI2 - (AH2 * AG2) -> -1832.1075 | AK2: =MIN(Q2*(1-U2), Scenario_Control!$B$2*Q2) -> 121.78 | AL2: =IF(F2<=7,1,0) -> 0 | AM2: =DATEDIF(Table1[[#This Row],[Country_FirstMonth]], Table1[[#This Row],[MonthDate]], "m") -> 14
A3: ORD-2024-358795 | B3: 45588 | C3: =IF(D3="Check",B3+7,E3) -> 45595 | D3: =IF(Table1[[#This Row],[RequiredDate]]<Table1[[#This Row],[OrderDate]],"Check","OK") -> Check | E3: 45587 | F3: =C3-B3 -> 7 | G3: Africa | H3: Nigeria | I3: Port Harcourt | J3: Education | K3: Online | L3: J. Njeri | M3: Printers | N3: PRN-9322 | O3: 1084.39 | P3: =IF(Table1[[#This Row],[UnitPrice]]<=0,"Check","OK") -> OK | Q3: =IF(R3<0,0,R3) -> 759.33 | R3: 759.33 | S3: =IF(Table1[[#This Row],[Discount_Flag]]="Check", MIN(MAX(Table1[[#This Row],[DiscountPct]],0),0.3), Table1[[#This Row],[DiscountPct]]) -> 0.237 | T3: =IF(OR(Table1[[#This Row],[DiscountPct]]<0,Table1[[#This Row],[DiscountPct]]>0.3),"Check","OK") -> OK | U3: 0.237 | V3: =IF(U3>0.2,1,0) -> 1 | W3: =IF(Z3=0, 0, Y3/Z3) -> -0.87167486 | X3: =O3*AD3 -> 33616.09 | Y3: =Z3-X3 -> -15655.658 | Z3: =Q3*AD3*(1-S3) -> 17960.432 | AA3: ="Q"&ROUNDUP(MONTH(B3)/3,0)&"-"&YEAR(B3) -> Q4-2024 | AB3: =TEXT(B3,"MMM-YYYY") -> Oct-2024 | AC3: =IF(Q3<=$AE$639,"Low",IF(Q3<=$AE$641,"Medium","High")) -> Medium | AD3: 31 | AE3: =_xlfn.MINIFS(Table1[MonthDate], Table1[Country], Table1[[#This Row],[Country]]) -> 44927 | AF3: =DATE(YEAR(B3), MONTH(B3), 1) -> 45566 | AG3: =AD3*(1 + Scenario_Control!$B$4) -> 34.1 | AH3: =O3*(1 + Scenario_Control!$B$3) -> 1138.6095 | AI3: =AK3 * AG3 * (1 - U3) -> 3951.2951 | AJ3: =AI3 - (AH3 * AG3) -> -34875.289 | AK3: =MIN(Q3*(1-U3), Scenario_Control!$B$2*Q3) -> 151.866 | AL3: =IF(F3<=7,1,0) -> 1 | AM3: =DATEDIF(Table1[[#This Row],[Country_FirstMonth]], Table1[[#This Row],[MonthDate]], "m") -> 21
A4: ORD-2023-373538 | B4: 44985 | C4: =IF(D4="Check",B4+7,E4) -> 45010 | D4: =IF(Table1[[#This Row],[RequiredDate]]<Table1[[#This Row],[OrderDate]],"Check","OK") -> OK | E4: 45010 | F4: =C4-B4 -> 25 | G4: Africa | H4: Kenya | I4: Nairobi | J4: Corporate | K4: Retail | L4: I. Johnson | M4: Networking | N4: NET-9666 | O4: 1460.76 | P4: =IF(Table1[[#This Row],[UnitPrice]]<=0,"Check","OK") -> Check | Q4: =IF(R4<0,0,R4) -> 0 | R4: -30.66 | S4: =IF(Table1[[#This Row],[Discount_Flag]]="Check", MIN(MAX(Table1[[#This Row],[DiscountPct]],0),0.3), Table1[[#This Row],[DiscountPct]]) -> 0.131 | T4: =IF(OR(Table1[[#This Row],[DiscountPct]]<0,Table1[[#This Row],[DiscountPct]]>0.3),"Check","OK") -> OK | U4: 0.131 | V4: =IF(U4>0.2,1,0) -> 0 | W4: =IF(Z4=0, 0, Y4/Z4) -> 0 | X4: =O4*AD4 -> 17529.12 | Y4: =Z4-X4 -> -17529.12 | Z4: =Q4*AD4*(1-S4) -> 0 | AA4: ="Q"&ROUNDUP(MONTH(B4)/3,0)&"-"&YEAR(B4) -> Q1-2023 | AB4: =TEXT(B4,"MMM-YYYY") -> Feb-2023 | AC4: =IF(Q4<=$AE$639,"Low",IF(Q4<=$AE$641,"Medium","High")) -> Low | AD4: 12 | AE4: =_xlfn.MINIFS(Table1[MonthDate], Table1[Country], Table1[[#This Row],[Country]]) -> 44927 | AF4: =DATE(YEAR(B4), MONTH(B4), 1) -> 44958 | AG4: =AD4*(1 + Scenario_Control!$B$4) -> 13.2 | AH4: =O4*(1 + Scenario_Control!$B$3) -> 1533.798 | AI4: =AK4 * AG4 * (1 - U4) -> 0 | AJ4: =AI4 - (AH4 * AG4) -> -20246.134 | AK4: =MIN(Q4*(1-U4), Scenario_Control!$B$2*Q4) -> 0 | AL4: =IF(F4<=7,1,0) -> 0 | AM4: =DATEDIF(Table1[[#This Row],[Country_FirstMonth]], Table1[[#This Row],[MonthDate]], "m") -> 1
A5: ORD-2025-168148 | B5: 45745 | C5: =IF(D5="Check",B5+7,E5) -> 45749 | D5: =IF(Table1[[#This Row],[RequiredDate]]<Table1[[#This Row],[OrderDate]],"Check","OK") -> OK | E5: 45749 | F5: =C5-B5 -> 4 | G5: Africa | H5: Nigeria | I5: Lagos | J5: Non-Profit | K5: Marketplace | L5: G. Dubois | M5: Phones | N5: PHN-4556 | O5: 259.93 | P5: =IF(Table1[[#This Row],[UnitPrice]]<=0,"Check","OK") -> OK | Q5: =IF(R5<0,0,R5) -> 255.94 | R5: 255.94 | S5: =IF(Table1[[#This Row],[Discount_Flag]]="Check", MIN(MAX(Table1[[#This Row],[DiscountPct]],0),0.3), Table1[[#This Row],[DiscountPct]]) -> 0.072 | T5: =IF(OR(Table1[[#This Row],[DiscountPct]]<0,Table1[[#This Row],[DiscountPct]]>0.3),"Check","OK") -> OK | U5: 0.072 | V5: =IF(U5>0.2,1,0) -> 0 | W5: =IF(Z5=0, 0, Y5/Z5) -> -0.094385335 | X5: =O5*AD5 -> 5718.46 | Y5: =Z5-X5 -> -493.18896 | Z5: =Q5*AD5*(1-S5) -> 5225.271 | AA5: ="Q"&ROUNDUP(MONTH(B5)/3,0)&"-"&YEAR(B5) -> Q1-2025 | AB5: =TEXT(B5,"MMM-YYYY") -> Mar-2025 | AC5: =IF(Q5<=$AE$639,"Low",IF(Q5<=$AE$641,"Medium","High")) -> Low | AD5: 22 | AE5: =_xlfn.MINIFS(Table1[MonthDate], Table1[Country], Table1[[#This Row],[Country]]) -> 44927 | AF5: =DATE(YEAR(B5), MONTH(B5), 1) -> 45717 | AG5: =AD5*(1 + Scenario_Control!$B$4) -> 24.2 | AH5: =O5*(1 + Scenario_Control!$B$3) -> 272.9265 | AI5: =AK5 * AG5 * (1 - U5) -> 1149.5596 | AJ5: =AI5 - (AH5 * AG5) -> -5455.2617 | AK5: =MIN(Q5*(1-U5), Scenario_Control!$B$2*Q5) -> 51.188 | AL5: =IF(F5<=7,1,0) -> 1 | AM5: =DATEDIF(Table1[[#This Row],[Country_FirstMonth]], Table1[[#This Row],[MonthDate]], "m") -> 26
A6: ORD-2023-824839 | B6: 45266 | C6: =IF(D6="Check",B6+7,E6) -> 45291 | D6: =IF(Table1[[#This Row],[RequiredDate]]<Table1[[#This Row],[OrderDate]],"Check","OK") -> OK | E6: 45291 | F6: =C6-B6 -> 25 | G6: Asia | H6: Japan | I6: Osaka | J6: Consumer | K6: Retail | L6: L. Okafor | M6: Printers | N6: PRN-8041 | O6: 663.03 | P6: =IF(Table1[[#This Row],[UnitPrice]]<=0,"Check","OK") -> OK | Q6: =IF(R6<0,0,R6) -> 813.51 | R6: 813.51 | S6: =IF(Table1[[#This Row],[Discount_Flag]]="Check", MIN(MAX(Table1[[#This Row],[DiscountPct]],0),0.3), Table1[[#This Row],[DiscountPct]]) -> 0.102 | T6: =IF(OR(Table1[[#This Row],[DiscountPct]]<0,Table1[[#This Row],[DiscountPct]]>0.3),"Check","OK") -> OK | U6: 0.102 | V6: =IF(U6>0.2,1,0) -> 0 | W6: =IF(Z6=0, 0, Y6/Z6) -> 0.092401129 | X6: =O6*AD6 -> 9945.45 | Y6: =Z6-X6 -> 1012.5297 | Z6: =Q6*AD6*(1-S6) -> 10957.98 | AA6: ="Q"&ROUNDUP(MONTH(B6)/3,0)&"-"&YEAR(B6) -> Q4-2023 | AB6: =TEXT(B6,"MMM-YYYY") -> Dec-2023 | AC6: =IF(Q6<=$AE$639,"Low",IF(Q6<=$AE$641,"Medium","High")) -> Medium | AD6: 15 | AE6: =_xlfn.MINIFS(Table1[MonthDate], Table1[Country], Table1[[#This Row],[Country]]) -> 44986 | AF6: =DATE(YEAR(B6), MONTH(B6), 1) -> 45261 | AG6: =AD6*(1 + Scenario_Control!$B$4) -> 16.5 | AH6: =O6*(1 + Scenario_Control!$B$3) -> 696.1815 | AI6: =AK6 * AG6 * (1 - U6) -> 2410.7555 | AJ6: =AI6 - (AH6 * AG6) -> -9076.2392 | AK6: =MIN(Q6*(1-U6), Scenario_Control!$B$2*Q6) -> 162.702 | AL6: =IF(F6<=7,1,0) -> 0 | AM6: =DATEDIF(Table1[[#This Row],[Country_FirstMonth]], Table1[[#This Row],[MonthDate]], "m") -> 9
A7: ORD-2023-723587 | B7: 44928 | C7: =IF(D7="Check",B7+7,E7) -> 44931 | D7: =IF(Table1[[#This Row],[RequiredDate]]<Table1[[#This Row],[OrderDate]],"Check","OK") -> OK | E7: 44931 | F7: =C7-B7 -> 3 | G7: Americas | H7: Canada | I7: Toronto | J7: Corporate | K7: Distributor | L7: B. Chen | M7: Laptops | N7: LAP-8555 | O7: 315.87 | P7: =IF(Table1[[#This Row],[UnitPrice]]<=0,"Check","OK") -> OK | Q7: =IF(R7<0,0,R7) -> 591.68 | R7: 591.68 | S7: =IF(Table1[[#This Row],[Discount_Flag]]="Check", MIN(MAX(Table1[[#This Row],[DiscountPct]],0),0.3), Table1[[#This Row],[DiscountPct]]) -> 0 | T7: =IF(OR(Table1[[#This Row],[DiscountPct]]<0,Table1[[#This Row],[DiscountPct]]>0.3),"Check","OK") -> OK | U7: 0 | V7: =IF(U7>0.2,1,0) -> 0 | W7: =IF(Z7=0, 0, Y7/Z7) -> 0.46614724 | X7: =O7*AD7 -> 2211.09 | Y7: =Z7-X7 -> 1930.67 | Z7: =Q7*AD7*(1-S7) -> 4141.76 | AA7: ="Q"&ROUNDUP(MONTH(B7)/3,0)&"-"&YEAR(B7) -> Q1-2023 | AB7: =TEXT(B7,"MMM-YYYY") -> Jan-2023 | AC7: =IF(Q7<=$AE$639,"Low",IF(Q7<=$AE$641,"Medium","High")) -> Low | AD7: 7 | AE7: =_xlfn.MINIFS(Table1[MonthDate], Table1[Country], Table1[[#This Row],[Country]]) -> 44927 | AF7: =DATE(YEAR(B7), MONTH(B7), 1) -> 44927 | AG7: =AD7*(1 + Scenario_Control!$B$4) -> 7.7 | AH7: =O7*(1 + Scenario_Control!$B$3) -> 331.6635 | AI7: =AK7 * AG7 * (1 - U7) -> 911.1872 | AJ7: =AI7 - (AH7 * AG7) -> -1642.6218 | AK7: =MIN(Q7*(1-U7), Scenario_Control!$B$2*Q7) -> 118.336 | AL7: =IF(F7<=7,1,0) -> 1 | AM7: =DATEDIF(Table1[[#This Row],[Country_FirstMonth]], Table1[[#This Row],[MonthDate]], "m") -> 0
A8: ORD-2024-336584 | B8: 45653 | C8: =IF(D8="Check",B8+7,E8) -> 45671 | D8: =IF(Table1[[#This Row],[RequiredDate]]<Table1[[#This Row],[OrderDate]],"Check","OK") -> OK | E8: 45671 | F8: =C8-B8 -> 18 | G8: Asia | H8: India | I8: Bengaluru | J8: Small Business | K8: Marketplace | L8: E. Garcia | M8: Monitors | N8: MON-8629 | O8: 586.07 | P8: =IF(Table1[[#This Row],[UnitPrice]]<=0,"Check","OK") -> OK | Q8: =IF(R8<0,0,R8) -> 845.97 | R8: 845.97 | S8: =IF(Table1[[#This Row],[Discount_Flag]]="Check", MIN(MAX(Table1[[#This Row],[DiscountPct]],0),0.3), Table1[[#This Row],[DiscountPct]]) -> 0.147 | T8: =IF(OR(Table1[[#This Row],[DiscountPct]]<0,Table1[[#This Row],[DiscountPct]]>0.3),"Check","OK") -> OK | U8: 0.147 | V8: =IF(U8>0.2,1,0) -> 0 | W8: =IF(Z8=0, 0, Y8/Z8) -> 0.1878327 | X8: =O8*AD8 -> 2344.28 | Y8: =Z8-X8 -> 542.16964 | Z8: =Q8*AD8*(1-S8) -> 2886.4496 | AA8: ="Q"&ROUNDUP(MONTH(B8)/3,0)&"-"&YEAR(B8) -> Q4-2024 | AB8: =TEXT(B8,"MMM-YYYY") -> Dec-2024 | AC8: =IF(Q8<=$AE$639,"Low",IF(Q8<=$AE$641,"Medium","High")) -> Medium | AD8: 4 | AE8: =_xlfn.MINIFS(Table1[MonthDate], Table1[Country], Table1[[#This Row],[Country]]) -> 44927 | AF8: =DATE(YEAR(B8), MONTH(B8), 1) -> 45627 | AG8: =AD8*(1 + Scenario_Control!$B$4) -> 4.4 | AH8: =O8*(1 + Scenario_Control!$B$3) -> 615.3735 | AI8: =AK8 * AG8 * (1 - U8) -> 635.01892 | AJ8: =AI8 - (AH8 * AG8) -> -2072.6245 | AK8: =MIN(Q8*(1-U8), Scenario_Control!$B$2*Q8) -> 169.194 | AL8: =IF(F8<=7,1,0) -> 0 | AM8: =DATEDIF(Table1[[#This Row],[Country_FirstMonth]], Table1[[#This Row],[MonthDate]], "m") -> 23
A9: ORD-2023-112666 | B9: 44941 | C9: =IF(D9="Check",B9+7,E9) -> 44948 | D9: =IF(Table1[[#This Row],[RequiredDate]]<Table1[[#This Row],[OrderDate]],"Check","OK") -> Check | E9: 44939 | F9: =C9-B9 -> 7 | G9: Africa | H9: Nigeria | I9: Abuja | J9: Education | K9: Online | L9: O. Wang | M9: Printers | N9: PRN-6276 | O9: 28.38 | P9: =IF(Table1[[#This Row],[UnitPrice]]<=0,"Check","OK") -> OK | Q9: =IF(R9<0,0,R9) -> 47.22 | R9: 47.22 | S9: =IF(Table1[[#This Row],[Discount_Flag]]="Check", MIN(MAX(Table1[[#This Row],[DiscountPct]],0),0.3), Table1[[#This Row],[DiscountPct]]) -> 0.194 | T9: =IF(OR(Table1[[#This Row],[DiscountPct]]<0,Table1[[#This Row],[DiscountPct]]>0.3),"Check","OK") -> OK | U9: 0.194 | V9: =IF(U9>0.2,1,0) -> 0 | W9: =IF(Z9=0, 0, Y9/Z9) -> 0.25432194 | X9: =O9*AD9 -> 510.84 | Y9: =Z9-X9 -> 174.22776 | Z9: =Q9*AD9*(1-S9) -> 685.06776 | AA9: ="Q"&ROUNDUP(MONTH(B9)/3,0)&"-"&YEAR(B9) -> Q1-2023 | AB9: =TEXT(B9,"MMM-YYYY") -> Jan-2023 | AC9: =IF(Q9<=$AE$639,"Low",IF(Q9<=$AE$641,"Medium","High")) -> Low | AD9: 18 | AE9: =_xlfn.MINIFS(Table1[MonthDate], Table1[Country], Table1[[#This Row],[Country]]) -> 44927 | AF9: =DATE(YEAR(B9), MONTH(B9), 1) -> 44927 | AG9: =AD9*(1 + Scenario_Control!$B$4) -> 19.8 | AH9: =O9*(1 + Scenario_Control!$B$3) -> 29.799 | AI9: =AK9 * AG9 * (1 - U9) -> 150.71491 | AJ9: =AI9 - (AH9 * AG9) -> -439.30529 | AK9: =MIN(Q9*(1-U9), Scenario_Control!$B$2*Q9) -> 9.444 | AL9: =IF(F9<=7,1,0) -> 1 | AM9: =DATEDIF(Table1[[#This Row],[Country_FirstMonth]], Table1[[#This Row],[MonthDate]], "m") -> 0
A10: ORD-2024-589570 | B10: 45416 | C10: =IF(D10="Check",B10+7,E10) -> 45441 | D10: =IF(Table1[[#This Row],[RequiredDate]]<Table1[[#This Row],[OrderDate]],"Check","OK") -> OK | E10: 45441 | F10: =C10-B10 -> 25 | G10: Africa | H10: Nigeria | I10: Abuja | J10: Non-Profit | K10: Marketplace | L10: O. Wang | M10: Monitors | N10: MON-6892 | O10: 1295.34 | P10: =IF(Table1[[#This Row],[UnitPrice]]<=0,"Check","OK") -> OK | Q10: =IF(R10<0,0,R10) -> 2530.81 | R10: 2530.81 | S10: =IF(Table1[[#This Row],[Discount_Flag]]="Check", MIN(MAX(Table1[[#This Row],[DiscountPct]],0),0.3), Table1[[#This Row],[DiscountPct]]) -> 0.031 | T10: =IF(OR(Table1[[#This Row],[DiscountPct]]<0,Table1[[#This Row],[DiscountPct]]>0.3),"Check","OK") -> OK | U10: 0.031 | V10: =IF(U10>0.2,1,0) -> 0 | W10: =IF(Z10=0, 0, Y10/Z10) -> 0.47179749 | X10: =O10*AD10 -> 7772.04 | Y10: =Z10-X10 -> 6942.0893 | Z10: =Q10*AD10*(1-S10) -> 14714.129 | AA10: ="Q"&ROUNDUP(MONTH(B10)/3,0)&"-"&YEAR(B10) -> Q2-2024 | AB10: =TEXT(B10,"MMM-YYYY") -> May-2024 | AC10: =IF(Q10<=$AE$639,"Low",IF(Q10<=$AE$641,"Medium","High")) -> High | AD10: 6 | AE10: =_xlfn.MINIFS(Table1[MonthDate], Table1[Country], Table1[[#This Row],[Country]]) -> 44927 | AF10: =DATE(YEAR(B10), MONTH(B10), 1) -> 45413 | AG10: =AD10*(1 + Scenario_Control!$B$4) -> 6.6 | AH10: =O10*(1 + Scenario_Control!$B$3) -> 1360.107 | AI10: =AK10 * AG10 * (1 - U10) -> 3237.1085 | AJ10: =AI10 - (AH10 * AG10) -> -5739.5977 | AK10: =MIN(Q10*(1-U10), Scenario_Control!$B$2*Q10) -> 506.162 | AL10: =IF(F10<=7,1,0) -> 0 | AM10: =DATEDIF(Table1[[#This Row],[Country_FirstMonth]], Table1[[#This Row],[MonthDate]], "m") -> 16
A11: ORD-2025-997421 | B11: 45798 | C11: =IF(D11="Check",B11+7,E11) -> 45817 | D11: =IF(Table1[[#This Row],[RequiredDate]]<Table1[[#This Row],[OrderDate]],"Check","OK") -> OK | E11: 45817 | F11: =C11-B11 -> 19 | G11: Americas | H11: Brazil | I11: São Paulo | J11: Non-Profit | K11: Online | L11: A. Patel | M11: Components | N11: CMP-3731 | O11: 1331.38 | P11: =IF(Table1[[#This Row],[UnitPrice]]<=0,"Check","OK") -> OK | Q11: =IF(R11<0,0,R11) -> 2309.56 | R11: 2309.56 | S11: =IF(Table1[[#This Row],[Discount_Flag]]="Check", MIN(MAX(Table1[[#This Row],[DiscountPct]],0),0.3), Table1[[#This Row],[DiscountPct]]) -> 0.149 | T11: =IF(OR(Table1[[#This Row],[DiscountPct]]<0,Table1[[#This Row],[DiscountPct]]>0.3),"Check","OK") -> OK | U11: 0.149 | V11: =IF(U11>0.2,1,0) -> 0 | W11: =IF(Z11=0, 0, Y11/Z11) -> 0.32260308 | X11: =O11*AD11 -> 41272.78 | Y11: =Z11-X11 -> 19655.722 | Z11: =Q11*AD11*(1-S11) -> 60928.502 | AA11: ="Q"&ROUNDUP(MONTH(B11)/3,0)&"-"&YEAR(B11) -> Q2-2025 | AB11: =TEXT(B11,"MMM-YYYY") -> May-2025 | AC11: =IF(Q11<=$AE$639,"Low",IF(Q11<=$AE$641,"Medium","High")) -> High | AD11: 31 | AE11: =_xlfn.MINIFS(Table1[MonthDate], Table1[Country], Table1[[#This Row],[Country]]) -> 44927 | AF11: =DATE(YEAR(B11), MONTH(B11), 1) -> 45778 | AG11: =AD11*(1 + Scenario_Control!$B$4) -> 34.1 | AH11: =O11*(1 + Scenario_Control!$B$3) -> 1397.949 | AI11: =AK11 * AG11 * (1 - U11) -> 13404.271 | AJ11: =AI11 - (AH11 * AG11) -> -34265.79 | AK11: =MIN(Q11*(1-U11), Scenario_Control!$B$2*Q11) -> 461.912 | AL11: =IF(F11<=7,1,0) -> 0 | AM11: =DATEDIF(Table1[[#This Row],[Country_FirstMonth]], Table1[[#This Row],[MonthDate]], "m") -> 28
A12: ORD-2024-210687 | B12: 45319 | C12: =IF(D12="Check",B12+7,E12) -> 45331 | D12: =IF(Table1[[#This Row],[RequiredDate]]<Table1[[#This Row],[OrderDate]],"Check","OK") -> OK | E12: 45331 | F12: =C12-B12 -> 12 | G12: Europe | H12: Germany | I12: Berlin | J12: Corporate | K12: Online | L12: G. Dubois | M12: Accessories | N12: ACC-7938 | O12: 644.17 | P12: =IF(Table1[[#This Row],[UnitPrice]]<=0,"Check","OK") -> OK | Q12: =IF(R12<0,0,R12) -> 700.12 | R12: 700.12 | S12: =IF(Table1[[#This Row],[Discount_Flag]]="Check", MIN(MAX(Table1[[#This Row],[DiscountPct]],0),0.3), Table1[[#This Row],[DiscountPct]]) -> 0.006 | T12: =IF(OR(Table1[[#This Row],[DiscountPct]]<0,Table1[[#This Row],[DiscountPct]]>0.3),"Check","OK") -> OK | U12: 0.006 | V12: =IF(U12>0.2,1,0) -> 0 | W12: =IF(Z12=0, 0, Y12/Z12) -> 0.074361038 | X12: =O12*AD12 -> 14815.91 | Y12: =Z12-X12 -> 1190.2334 | Z12: =Q12*AD12*(1-S12) -> 16006.143 | AA12: ="Q"&ROUNDUP(MONTH(B12)/3,0)&"-"&YEAR(B12) -> Q1-2024 | AB12: =TEXT(B12,"MMM-YYYY") -> Jan-2024 | AC12: =IF(Q12<=$AE$639,"Low",IF(Q12<=$AE$641,"Medium","High")) -> Medium | AD12: 23 | AE12: =_xlfn.MINIFS(Table1[MonthDate], Table1[Country], Table1[[#This Row],[Country]]) -> 44927 | AF12: =DATE(YEAR(B12), MONTH(B12), 1) -> 45292 | AG12: =AD12*(1 + Scenario_Control!$B$4) -> 25.3 | AH12: =O12*(1 + Scenario_Control!$B$3) -> 676.3785 | AI12: =AK12 * AG12 * (1 - U12) -> 3521.3516 | AJ12: =AI12 - (AH12 * AG12) -> -13591.024 | AK12: =MIN(Q12*(1-U12), Scenario_Control!$B$2*Q12) -> 140.024 | AL12: =IF(F12<=7,1,0) -> 0 | AM12: =DATEDIF(Table1[[#This Row],[Country_FirstMonth]], Table1[[#This Row],[MonthDate]], "m") -> 12
A13: ORD-2025-515515 | B13: 45660 | C13: =IF(D13="Check",B13+7,E13) -> 45680 | D13: =IF(Table1[[#This Row],[RequiredDate]]<Table1[[#This Row],[OrderDate]],"Check","OK") -> OK | E13: 45680 | F13: =C13-B13 -> 20 | G13: Asia | H13: Japan | I13: Osaka | J13: Corporate | K13: Distributor | L13: F. Müller | M13: Phones | N13: PHN-7019 | O13: 908.6 | P13: =IF(Table1[[#This Row],[UnitPrice]]<=0,"Check","OK") -> OK | Q13: =IF(R13<0,0,R13) -> 691.37 | R13: 691.37 | S13: =IF(Table1[[#This Row],[Discount_Flag]]="Check", MIN(MAX(Table1[[#This Row],[DiscountPct]],0),0.3), Table1[[#This Row],[DiscountPct]]) -> 0.25 | T13: =IF(OR(Table1[[#This Row],[DiscountPct]]<0,Table1[[#This Row],[DiscountPct]]>0.3),"Check","OK") -> OK | U13: 0.25 | V13: =IF(U13>0.2,1,0) -> 1 | W13: =IF(Z13=0, 0, Y13/Z13) -> -0.75226965 | X13: =O13*AD13 -> 18172 | Y13: =Z13-X13 -> -7801.45 | Z13: =Q13*AD13*(1-S13) -> 10370.55 | AA13: ="Q"&ROUNDUP(MONTH(B13)/3,0)&"-"&YEAR(B13) -> Q1-2025 | AB13: =TEXT(B13,"MMM-YYYY") -> Jan-2025 | AC13: =IF(Q13<=$AE$639,"Low",IF(Q13<=$AE$641,"Medium","High")) -> Medium | AD13: 20 | AE13: =_xlfn.MINIFS(Table1[MonthDate], Table1[Country], Table1[[#This Row],[Country]]) -> 44986 | AF13: =DATE(YEAR(B13), MONTH(B13), 1) -> 45658 | AG13: =AD13*(1 + Scenario_Control!$B$4) -> 22 | AH13: =O13*(1 + Scenario_Control!$B$3) -> 954.03 | AI13: =AK13 * AG13 * (1 - U13) -> 2281.521 | AJ13: =AI13 - (AH13 * AG13) -> -18707.139 | AK13: =MIN(Q13*(1-U13), Scenario_Control!$B$2*Q13) -> 138.274 | AL13: =IF(F13<=7,1,0) -> 0 | AM13: =DATEDIF(Table1[[#This Row],[Country_FirstMonth]], Table1[[#This Row],[MonthDate]], "m") -> 22
... A633: ORD-2025-728935 | B633: 45716 | C633: =IF(D633="Check",B633+7,E633) -> 45726 | D633: =IF(Table1[[#This Row],[RequiredDate]]<Table1[[#This Row],[OrderDate]],"Check","OK") -> OK | E633: 45726 | F633: =C633-B633 -> 10 | G633: Asia | H633: Japan | I633: Osaka | J633: Education | K633: Distributor | L633: N. Brown | M633: Laptops | N633: LAP-3017 | O633: 51.86 | P633: =IF(Table1[[#This Row],[UnitPrice]]<=0,"Check","OK") -> OK | Q633: =IF(R633<0,0,R633) -> 45.98 | R633: 45.98 | S633: =IF(Table1[[#This Row],[Discount_Flag]]="Check", MIN(MAX(Table1[[#This Row],[DiscountPct]],0),0.3), Table1[[#This Row],[DiscountPct]]) -> 0.173 | T633: =IF(OR(Table1[[#This Row],[DiscountPct]]<0,Table1[[#This Row],[DiscountPct]]>0.3),"Check","OK") -> OK | U633: 0.173 | V633: =IF(U633>0.2,1,0) -> 0 | W633: =IF(Z633=0, 0, Y633/Z633) -> -0.36382308 | X633: =O633*AD633 -> 363.02 | Y633: =Z633-X633 -> -96.84178 | Z633: =Q633*AD633*(1-S633) -> 266.17822 | AA633: ="Q"&ROUNDUP(MONTH(B633)/3,0)&"-"&YEAR(B633) -> Q1-2025 | AB633: =TEXT(B633,"MMM-YYYY") -> Feb-2025 | AC633: =IF(Q633<=$AE$639,"Low",IF(Q633<=$AE$641,"Medium","High")) -> Low | AD633: 7 | AE633: =_xlfn.MINIFS(Table1[MonthDate], Table1[Country], Table1[[#This Row],[Country]]) -> 44986 | AF633: =DATE(YEAR(B633), MONTH(B633), 1) -> 45689 | AG633: =AD633*(1 + Scenario_Control!$B$4) -> 7.7 | AH633: =O633*(1 + Scenario_Control!$B$3) -> 54.453 | AI633: =AK633 * AG633 * (1 - U633) -> 58.559208 | AJ633: =AI633 - (AH633 * AG633) -> -360.72889 | AK633: =MIN(Q633*(1-U633), Scenario_Control!$B$2*Q633) -> 9.196 | AL633: =IF(F633<=7,1,0) -> 0 | AM633: =DATEDIF(Table1[[#This Row],[Country_FirstMonth]], Table1[[#This Row],[MonthDate]], "m") -> 23
AE638: Price Q1
AE639: =_xlfn.QUARTILE.INC(Table1[UnitPrice_Clean],1) -> 606.3775
AE640: Price Q2
AE641: =_xlfn.QUARTILE.INC(Table1[UnitPrice_Clean],3) -> 1912.045

Sheet Read Me
B1: PART A:1
B2: 1.Duplicates were defined as rows sharing same OderID, SKU, OderDate and Quantity. Using Excel's remove duplicate tool, 0 duplicate rows were removed.
B3: 2.OrderDate and RequiredDate were validated and converted to true date formats. UnitCost, UnitPrice, Quantity, and DiscountPct were validated as numeric fields. DiscountPct is stored as decimal values
B4: 3.DiscountPct is stored as a decimal (e.g., 0.237 = 23.7%) and was formatted as a percentage for readability.
B6: 4.Missing City values were filled with ‘Unknown’ where Country-level inference was ambiguous due to multiple cities per country.
B7: 5.Missing Channel values could not be reliably inferred from other fields and were therefore labeled as ‘Unknown’ to avoid introducing assumptions
B8: 6.Missing Salesperson values were labeled as ‘Unassigned’. Existing names were preserved. No inference was made to avoid introducing bias.
B9: 7.UnitPrice values less than or equal to 0 were flagged as ‘Check’ using a helper column and later converted to 0 in new column UnitPrices_Clean. These rows were highlighted with conditional formatting in red to indicate suspicious values.
B10: 8.DiscountPct values greater than 30% were capped at 30%, and negative discounts were set to 0. Original values were flagged using a helper column and conditional formatting for audit purposes.
B11: 9.Some RequiredDate values were earlier than OrderDate. These were flagged and corrected by setting RequiredDate = OrderDate + 7 days, assuming a minimum 7-day lead time. LeadTimeDays was then calculated as RequiredDate − OrderDate.
B12: 10.Negative UnitPrice values were replaced with 0 in a new column UnitPrice_Clean to ensure all revenue and profit calculations are valid.
B13: 11. All calculated columns (GrossRevenue, CostOfGoods, GrossProfit, MarginPct) use this cleaned UnitPrice column. Basic Excel functions (-),(*) and (/) were used for the calculations.
... B45: Discount outliers visualized using Box & Whisker

Sheet Brief
A1: Assignment
A2: Excel Mastery Assignment: Sales Operations & Analytics
A4: Overview:
A5: You are an analyst for a multi-regional electronics distributor. The 'Data' sheet contains 632 rows and 15 columns of transactional data with intentional data-quality issues.
A6: Your job is to clean, enrich, analyze, and present insights via a dynamic dashboard.
A8: Part A — Data Cleaning & Preparation:
A9: 1) Create a staging table where you:
A10: • Remove exact duplicate rows (define and document your duplicate criteria).
A11: • Fix data types (dates as Dates, numeric fields as numbers).
A12: • Handle missing values for City, Salesperson, and Channel using reasonable business logic (document your approach).
A13: • Flag and correct suspicious UnitPrice values (e.g., negative prices) and discounts (e.g., > 30%).
A14: • Ensure RequiredDate is not earlier than OrderDate; where it is, impute a corrected RequiredDate (explain your rule).
... A67: 15) Ensure your dashboard responds to slicers without broken references.

Sheet Scenario_Control
A1: Parameter | B1: Value
A2: Discount Cap | B2: 0.2
A3: UnitCost Inflation | B3: 0.05
A4: Quantity Uplift | B4: 0.1
E7: Metric | F7: Baseline | G7: Scenario
E8: Total Revenue | F8: =SUM(Data_staging!Z:Z) -> 10944329 | G8: =SUM(Data_staging!AI:AI) -> 2404029.5
E9: Gross Profit | F9: =SUM(Data_staging!Y:Y) -> 3416581.1 | G9: =SUM(Data_staging!AJ:AJ) -> -6290519.1
E10: Margin % | F10: =IF(SUM(Data_staging!Z:Z)=0,0,SUM(Data_staging!Y:Y)/SUM(Data_staging!Z:Z)) -> 0.31217822 | G10: =IF(SUM(Data_staging!AI:AI)=0,0,SUM(Data_staging!AJ:AJ)/SUM(Data_staging!AI:AI)) -> -2.6166564

Sheet Dashboard
B2: ="Revenue by Month | Region: " & IF(B3="(All)","All Regions",B3) -> Revenue by Month | Region: Africa
B3: =Sheet18!A4 -> Africa
